# setTimeout でのエラー

<<<<<<< HEAD:1-js/11-async/03-promise-chaining/02-error-async/task.md
`.catch` はトリガされると思いますか？またその理由を説明できますか？
=======
What do you think? Will the `.catch` trigger? Explain your answer.
>>>>>>> 30f1dc4e4ed9e93b891abd73f27da0a47c5bf613:1-js/11-async/04-promise-error-handling/01-error-async/task.md

```js
new Promise(function(resolve, reject) {
  setTimeout(() => {
    throw new Error("Whoops!");
  }, 1000);
}).catch(alert);
```
